# 异常与异常捕获

## 异常概述

异常是指在计算机运行过程中出现的非正常情况：用户非法输入，除数为零，文件不存在，数组下标越界等情况。

### java异常体系结构

`java`中的异常有很多类型，异常在`java`中被封装成了各种异常类：

所有的异常类都是`Throwable`类的子类，它派生出两个子类，`Error`类和`Exception`类。

1. `Error`类：表示程序无法恢复的严重错误或者恢复起来比较麻烦的错误，例如内存溢出、动态链接失败，虚拟机错误等。
2. `Exception`类：由java应用程序抛出和处理的非严重错误，例如：用户非法输入，除数为零，文件不存在，数组下标越界等情况。

不受检异常：也称为`unchecked`异常，包括`RuntimeException`及其所有子类。

受检异常：也称为`checked`异常，指除了不受检异常外，其他继承自`Exception`类的异常。对这类异常要求在代码中进行显式处理。

## 异常处理机制

### 异常处理

`java`的异常处理机制类似于人们对可能发生的意外情况进行预先处理的方式。在执行程序过程中，如果发生了异常，程序会按照预定的处理方式对异常进行处理。处理完异常后，程序会继续执行。如果异常没有被处理，程序将终止运行。

1. 用`try`、`catch`、`finally`来捕获和处理异常
   `try`块中包含可能会抛出异常的代码
   `catch`块中用于捕获并处理指定类型的异常
   `finally`块中的代码无论是否发生异常都会被执行，通常用于清理资源或清理操作
2. 使用`throw`、`throws`来抛出异常
   `throw`关键字用于手动抛出异常对象
   `throws`关键字用于在方法声明中指定可能抛出的异常类型，表示该方法可能会抛出该类型的异常，由调用者来处理。

### 捕获异常

1. 使用`try-catch`处理异常

   > 把可能出现异常的代码放在`tyr`代码块中，并使用`catch`语句块捕获异常。
   >
   > ```java
   > public class Main {
   >  public static void main(String[] args) {
   >      try {
   >          int i = 1, j = 0, res;
   >          System.out.println("begin");
   >          res = i / j;
   >          System.out.println("end");
   >      }catch (Exception e){
   >          System.out.println("caught");
   >          e.printStackTrace();
   >      }
   >      System.out.println("over");
   >  }
   > }
   > ```
   >
   > ![image-20230830191709893](https://s2.loli.net/2023/08/30/CMabkvmJqXWYSgT.png)
   >
   > - 如果`try`语句块中的所有语句正常执行完毕，没有发生异常，那么`catch`语句块中的所有语句都将被忽略。
   > - 如果`try`语句块在执行过程中发生异常，并且这个异常与`catch`语句块中声明的异常类型匹配，那么`try`语句块中剩下的代码都将被忽略，而相应的`catch`语句块将会被执行。匹配是指`catch`所处理的异常类型与`try`块所生成的异常类型完全一致或是它的父类。
   > - 如果`try`语句块在执行过程中发生异常，而抛出的异常在`catch`语句块中没有被声明，那么程序立即终止运行，程序被强迫退出。
   > - `catch`语句块中可以加入用戶自定义处理信息，也可以调用异常对象的方法输出异常信息，常用的方法如下：
   >   `void prinStackTrace()` ：输出异常的堆栈信息。堆栈信息包括程序运行到当前类的执行流程，它将输出从方法调用处到异常抛出处的方法调用的栈序列。
   >   `String getMessage()` ：返回异常信息描述字符串，该字符串描述了异常产生的原因，是 `printStackTrace()` 输出信息的一部分。
   >
   > 当异常发生时，可以调用 `printStackTrace()` 方法来输出异常的详细信息，包括异常类型、异常消息以及异常发生的调用栈信息。调用栈信息显示了异常发生的位置和调用链，可以帮助开发人员追踪和调试异常。
   
2. 使用`try-catch-finally`处理异常

   > `try-catch-finally`语句块组合使用时，无论try块中是否发生异常，finally语句块中的代码总能被执行。
   >
   > eg:
   >
   > ```java
   > public class Main {
   > 	public static void main(String[] args) {
   > 		try {
   > 			int i = 1, j = 0, res;
   > 			System.out.println("begin");
   > 			res = i / j;
   > 			System.out.println("end");
   > 		} catch (ArithmeticException e) {
   > 			System.out.println("caught");
   > 			e.printStackTrace();
   > 		} finally {
   > 			System.out.println("finally");
   > 		}
   > 		System.out.println("over");
   > 	}
   > }
   > ```
   >
   > 输出结果输出了“finally”。如果将j的值改为不是0，再次运行该程序，也会输出“finally”。
   > try-catch-finally语句块执行流程大致分为如下两种情况。
   >
   > 1. 如果`try`语句块中所有语句正常执行完毕，程序不会进入`catch`语句块执行，但是`finally`语句块会被执行。
   > 2. 如果`try`语句块在执行过程中发生异常，程序会进入到`catch`语句块捕获异,`finally`语句块也会被执行。
   > 3. `try-catch-finally`结构中try语句块是必须存在的，`catch`、`finally`语句块为可选，但两者至少出现其中之一。
   >
   > 即使在catch语句块中存在return语句，finally语句块中的语句也会执行。发生异常时的执行顺序是，先执行catch语句块中return之前的语句，再执行finally语句块中的语句，最后执行catch语句块中的return语句退出。
   >
   > finally语句块中语句不执行的唯一情况是在异常处理代码中执行了 System.exit(1) ，退出Java虚拟机。

3. 使用多重catch处理异常
   当一段代码可能引发多种类型的异常时，可以在一个try语句块后面跟随多个catch语句块，分别处理不同类型的异常。

   > `catch`语句块的排列顺序必须是从子类到父类，最后一个一般是`Exception`类。这是因为在异常处理中，`catch`语句块会按照从上到下的顺序进行匹配，系统会检测每个`catch`语句块处理的异常类型，并执行第一个与异常类型匹配的`catch`语句块。如果将父类异常放在前面，子类异常的`catch`语句块将永远不会被执行，因为父类异常的`catch`语句块已经处理了异常。

   一旦系统执行了与异常类型匹配的catch语句块，并执行其中的一条catch语句后，其后的catch语句块将被忽略，程序将继续执行紧随catch语句块的代码。

### 抛出异常

#### 使用throws声明抛出异常

`try-catch-finally`处理的是在一个方法内部发生的异常，在方法内部直接捕获并处理。如果在一个方法体内抛出了异常，并希望调用者能够及时的捕获异常，`java`语言中通过关键字`throws`声明某个方法可能抛出的各种异常，以通知调用者。`throws`可以同时声明多个异常，之间用逗号隔开。

```java
public void test() throws Exception{
    
}
```

#### 使用throw抛出异常

除了系统自动抛出异常外，在编程过程中，有些问题是系统无法自动发现并解决的，如果年龄不在正常范围之内，用户输入内容非法时，此时需要程序员而不是系统来自行抛出异常，把问题提交给调用者去解决。在`java`语言中，可以使用`throw`关键字来自行抛出异常。

```java
throw new Exception("message")
```

- 如果 `throw` 语句抛出的异常是 `Checked` 异常，则该 `throw` 语句要么处于 `try` 块里，显式捕获该异常，要么放在一个带 `throws` 声明抛出的方法中，即把该异常交给该方法的调用者处理；
- 如果 `throw` 语句抛出的异常是 `Runtime` 异常，则该语句无须放在 `try` 块里，也无须放在带 `throws` 声明抛出的方法中；程序既可以显式使用 `try...catch`来捕获并处理该异常，也可以完全不理会该异常，把该异常交给该方法调用者处理

#### 二者的区别

1. 作用不同：`throw`用于程序员自行产生并抛出的异常，`throws`用于声明该方法内抛出了异常。
2. 使用位置不同：`throw`位于方法体内部，可以作为单独的语句使用；`throws`必须跟在方法参数列表的后面，不能单独使用。
3. 内容不同：`throw`抛出一个异常对象，只能是一个；`throws`后面跟异常类，可以跟多个。

## 自定义异常

> 需求：写一个`saveAge(int age)`方法，在方法中对参数age进行判断，如果age<0或者>=150就认为年龄不合法，如果年龄不合法，就给调用者抛出一个年龄非法异常。
>
> 分析：Java的API中是没有年龄非常这个异常的，所以我们可以自定义一个异常类，用来表示年龄非法异常，然后再方法中抛出自定义异常即可。

- 先写一个异常类`AgeIllegalException`（异常名自行定义），继承

```java
// 1、必须让这个类继承自Exception，才能成为一个编译时异常类。
public class AgeIllegalException extends Exception{
	public AgeIllegalException() {
	}
public AgeIllegalException(String message) {
		super(message);
	}
}
```

- 再写一个测试类，在测试类中定义一个`saveAge(int age)`方法，对`age`判断如果年龄不在0~150之间，就抛出一个`AgeIllegalException`异常对象给调用者。

```java
public class ExceptionTest2 {
	public static void main(String[] args) {
	// 需求：保存一个合法的年
		try {
			saveAge2(225);
			System.out.println("saveAge2底层执行是成功的！");
		} catch (AgeIllegalException e) {
			e.printStackTrace();
			System.out.println("saveAge2底层执行是出现bug的！");
		}			
	}
	//2、在方法中对age进行判断，不合法则抛出AgeIllegalException
	public static void saveAge(int age){
		if(age > 0 && age < 150){
		System.out.println("年龄被成功保存： " + age);
		}else {
// 用一个异常对象封装这个问题
// throw 抛出去这个异常对象
		throw new AgeIllegalRuntimeException("/age is illegal, your age is 			" + age);
		}
	}
}
```

**注意：**自定义异常可以是编译时异常，也可以是运行时异常。

> 1.如果自定义异常类继承Excpetion，则是编译时异常。
> 特点：方法中抛出的是编译时异常，必须在方法上使用throws声明，强制调用者处理。
> 2.如果自定义异常类继承RuntimeException，则运行时异常。
> 特点：方法中抛出的是运行时异常，不需要在方法上用throws声明.

异常链：有时候我们会捕获一个异常后再抛出另一个异常

顾名思义就是将异常发生的原因一个传一个串起来，即把底层的异常信息传给上层这样逐层抛出。

定义`testOne`，`testTwo`，`testThree`方法，`testTwo`对`testOne`抛出的异常进行捕获，`testThree`对`testTwo`抛出的异常进行捕获：

```java
public class TryDemoFive {
public static void main(String[] args) {
try {
testThree();
} catch (Exception e) {
e.printStackTrace(); //
}
}
public static void testOne() throws MyException {
throw new MyException("我是一个异常");
}
public static void testTwo() throws Exception {
try {
testOne();
} catch (Exception e) {
throw new Exception("我是新产生的异常1");
}
}
public static void testThree() throws Exception {
try {
testTwo();
} catch (Exception e) {
throw new Exception("我是新产生的异常2");
}
}
}
```

- 直接在新抛出的异常中添加原来的异常信息

```java
throw new Exception("我是新产生的异常1", e);
```

- 在要抛出的对象中使用` initCause()` 方法，添加上一个产生异常的信息; `getCause() `可以获取当前异常对象的上一个异常对象

```java
Exception e2 = new Exception("我是新产生的异常2");
e2.initCause(e);
throw e2;
```